Workbook

Sheet README
A1: Lampiran Data Riset Bona Project: Kualitas Air Danau Toba (Sentinel-2)
A2: Disusun 12 Oktober 2026 dari ekspor Google Earth Engine tim (7 Oktober 2026). Semua angka indeks bersifat RELATIF, bukan mg/m3 atau NTU.
A4: Sheet | B4: Isi
A5: V3_Utama | B5: Versi data yang dipakai untuk interpretasi. KJA = Paropo (lon 98,522 sampai 98,531; lat 2,80 sampai 2,89). Referensi = lon 98,80 sampai 98,86; lat 2,66 sampai 2,72 (perlu cek visual).
A6: V1_Zona_Awal | B6: Versi pertama dengan kotak zona perkiraan (bukan lokasi keramba terverifikasi). Disimpan sebagai pembanding saja.
A7: V2_Ditolak | B7: Versi dengan kotak referensi selatan (lon 98,82 sampai 98,88; lat 2,50 sampai 2,56). DITOLAK: referensi terkontaminasi, 40 dari 66 bulan TURB > 100.
A8: Titik_Lapangan | B8: Nilai satelit di titik tepian Balige, komposit Juli 2025, buffer 30 m. Dua versi titik.
A9: Ringkasan | B9: Statistik per versi (rumus) dan hasil uji statistik (dihitung dengan Python scipy).
A10: Musiman | B10: Median NDCI per bulan kalender dari V3 yang lolos QC (rumus).
A12: Kolom | B12: Arti
A13: date | B13: Bulan komposit (YYYY-MM). Satu nilai = median semua citra bebas awan di bulan itu.
A14: zone | B14: KJA (zona keramba) atau Reference (zona pembanding).
A15: NDCI | B15: Normalized Difference Chlorophyll Index = (B5 - B4)/(B5 + B4). Makin tinggi = indikasi klorofil-a (alga) makin banyak. Rata-rata seluruh piksel air dalam kotak.
A16: TURB | B16: Proksi kekeruhan = reflektansi band merah B4 x 1000. Air jernih sekitar 5 sampai 40. Di atas 100 hampir pasti tercampur awan, kabut, atau daratan.
... A18: QC_lolos | B18: TRUE bila NDCI ada, TURB <= 100, dan n_images >= 2. Hanya baris TRUE dipakai di analisis.
A20: Sumber file asli di Google Drive (folder My Drive):
A21: V3 | B21: https://drive.google.com/file/d/1b_0Q5HlWY4NfYrzjWY08WV9zTJo7HtMb/view (identik dengan 1GcGhze4Jbh1P5YxNwWfroDI9NP-a73BU)
A22: V2 | B22: https://drive.google.com/file/d/1yXiGc5Gnazpa-Bose4DyeKXM-xyntYzF/view
A23: V1 | B23: https://drive.google.com/file/d/1g52wovvCVMzjGPqYC0llHI7yytGC0Tck/view (versi sampai Des 2025: 1W6YrURNq2lhRsRCjc3qSvwjoX95MHX4I)
A24: Titik lapangan | B24: https://drive.google.com/file/d/1RO-ELpeTa7gLdr7mtB0ugAx6dfGlviht/view dan versi lama 176MAScnk7Ie8GS9Vk1pb7cUkuNif8A3y

Sheet V3_Utama
A1: date | B1: tahun | C1: bulan | D1: zone | E1: NDCI | F1: TURB | G1: n_images | H1: QC_lolos | J1: Versi utama untuk interpretasi.
A2: 2019-01 | B2: =VALUE(LEFT(A2,4)) -> 2019 | C2: =VALUE(RIGHT(A2,2)) -> 1 | D2: KJA | E2: 0.04955 | F2: 31.35 | G2: 7 | H2: =AND(E2<>"",F2<=100,G2>=2) -> TRUE
A3: 2019-01 | B3: =VALUE(LEFT(A3,4)) -> 2019 | C3: =VALUE(RIGHT(A3,2)) -> 1 | D3: Reference | E3: 0.044129 | F3: 37.592 | G3: 7 | H3: =AND(E3<>"",F3<=100,G3>=2) -> TRUE
A4: 2019-02 | B4: =VALUE(LEFT(A4,4)) -> 2019 | C4: =VALUE(RIGHT(A4,2)) -> 2 | D4: KJA | E4: 0.007938 | F4: 23.965 | G4: 15 | H4: =AND(E4<>"",F4<=100,G4>=2) -> TRUE
A5: 2019-02 | B5: =VALUE(LEFT(A5,4)) -> 2019 | C5: =VALUE(RIGHT(A5,2)) -> 2 | D5: Reference | E5: 0.011232 | F5: 38.206 | G5: 15 | H5: =AND(E5<>"",F5<=100,G5>=2) -> TRUE
A6: 2019-03 | B6: =VALUE(LEFT(A6,4)) -> 2019 | C6: =VALUE(RIGHT(A6,2)) -> 3 | D6: KJA | E6: 0.021139 | F6: 25.434 | G6: 18 | H6: =AND(E6<>"",F6<=100,G6>=2) -> TRUE
A7: 2019-03 | B7: =VALUE(LEFT(A7,4)) -> 2019 | C7: =VALUE(RIGHT(A7,2)) -> 3 | D7: Reference | E7: -0.003695 | F7: 20.3 | G7: 18 | H7: =AND(E7<>"",F7<=100,G7>=2) -> TRUE
A8: 2019-04 | B8: =VALUE(LEFT(A8,4)) -> 2019 | C8: =VALUE(RIGHT(A8,2)) -> 4 | D8: KJA | E8: -0.051617 | F8: 14.613 | G8: 5 | H8: =AND(E8<>"",F8<=100,G8>=2) -> TRUE
A9: 2019-04 | B9: =VALUE(LEFT(A9,4)) -> 2019 | C9: =VALUE(RIGHT(A9,2)) -> 4 | D9: Reference | E9: -0.024626 | F9: 24.849 | G9: 5 | H9: =AND(E9<>"",F9<=100,G9>=2) -> TRUE
A10: 2019-05 | B10: =VALUE(LEFT(A10,4)) -> 2019 | C10: =VALUE(RIGHT(A10,2)) -> 5 | D10: KJA | E10: -0.01175 | F10: 14.712 | G10: 8 | H10: =AND(E10<>"",F10<=100,G10>=2) -> TRUE
A11: 2019-05 | B11: =VALUE(LEFT(A11,4)) -> 2019 | C11: =VALUE(RIGHT(A11,2)) -> 5 | D11: Reference | E11: 0.028593 | F11: 20.283 | G11: 8 | H11: =AND(E11<>"",F11<=100,G11>=2) -> TRUE
A12: 2019-06 | B12: =VALUE(LEFT(A12,4)) -> 2019 | C12: =VALUE(RIGHT(A12,2)) -> 6 | D12: KJA | E12: 0.05757 | F12: 19.551 | G12: 3 | H12: =AND(E12<>"",F12<=100,G12>=2) -> TRUE
A13: 2019-06 | B13: =VALUE(LEFT(A13,4)) -> 2019 | C13: =VALUE(RIGHT(A13,2)) -> 6 | D13: Reference | E13: 0.082681 | F13: 15.376 | G13: 3 | H13: =AND(E13<>"",F13<=100,G13>=2) -> TRUE
... A17: 2019-08 | B17: =VALUE(LEFT(A17,4)) -> 2019 | C17: =VALUE(RIGHT(A17,2)) -> 8 | D17: Reference | E17: 0.027122 | F17: 26.71 | G17: 7 | H17: =AND(E17<>"",F17<=100,G17>=2) -> TRUE
A18: 2019-09 | B18: =VALUE(LEFT(A18,4)) -> 2019 | C18: =VALUE(RIGHT(A18,2)) -> 9 | D18: KJA | G18: 0 | H18: =AND(E18<>"",F18<=100,G18>=2) -> FALSE
A19: 2019-09 | B19: =VALUE(LEFT(A19,4)) -> 2019 | C19: =VALUE(RIGHT(A19,2)) -> 9 | D19: Reference | G19: 0 | H19: =AND(E19<>"",F19<=100,G19>=2) -> FALSE
A20: 2019-10 | B20: =VALUE(LEFT(A20,4)) -> 2019 | C20: =VALUE(RIGHT(A20,2)) -> 10 | D20: KJA | G20: 2 | H20: =AND(E20<>"",F20<=100,G20>=2) -> FALSE
A21: 2019-10 | B21: =VALUE(LEFT(A21,4)) -> 2019 | C21: =VALUE(RIGHT(A21,2)) -> 10 | D21: Reference | E21: -0.026305 | F21: 11.182 | G21: 2 | H21: =AND(E21<>"",F21<=100,G21>=2) -> TRUE
A22: 2019-11 | B22: =VALUE(LEFT(A22,4)) -> 2019 | C22: =VALUE(RIGHT(A22,2)) -> 11 | D22: KJA | G22: 5 | H22: =AND(E22<>"",F22<=100,G22>=2) -> FALSE
A23: 2019-11 | B23: =VALUE(LEFT(A23,4)) -> 2019 | C23: =VALUE(RIGHT(A23,2)) -> 11 | D23: Reference | E23: 0.00304 | F23: 48.02 | G23: 5 | H23: =AND(E23<>"",F23<=100,G23>=2) -> TRUE
A24: 2019-12 | B24: =VALUE(LEFT(A24,4)) -> 2019 | C24: =VALUE(RIGHT(A24,2)) -> 12 | D24: KJA | E24: 0.014552 | F24: 26.983 | G24: 6 | H24: =AND(E24<>"",F24<=100,G24>=2) -> TRUE
A25: 2019-12 | B25: =VALUE(LEFT(A25,4)) -> 2019 | C25: =VALUE(RIGHT(A25,2)) -> 12 | D25: Reference | E25: 0.022083 | F25: 60.609 | G25: 6 | H25: =AND(E25<>"",F25<=100,G25>=2) -> TRUE
A26: 2020-01 | B26: =VALUE(LEFT(A26,4)) -> 2020 | C26: =VALUE(RIGHT(A26,2)) -> 1 | D26: KJA | E26: 0.034592 | F26: 21.633 | G26: 12 | H26: =AND(E26<>"",F26<=100,G26>=2) -> TRUE
A27: 2020-01 | B27: =VALUE(LEFT(A27,4)) -> 2020 | C27: =VALUE(RIGHT(A27,2)) -> 1 | D27: Reference | E27: -0.020987 | F27: 22.113 | G27: 12 | H27: =AND(E27<>"",F27<=100,G27>=2) -> TRUE
A28: 2020-02 | B28: =VALUE(LEFT(A28,4)) -> 2020 | C28: =VALUE(RIGHT(A28,2)) -> 2 | D28: KJA | E28: 0.033288 | F28: 26.794 | G28: 12 | H28: =AND(E28<>"",F28<=100,G28>=2) -> TRUE
A29: 2020-02 | B29: =VALUE(LEFT(A29,4)) -> 2020 | C29: =VALUE(RIGHT(A29,2)) -> 2 | D29: Reference | E29: 0.033676 | F29: 17.087 | G29: 12 | H29: =AND(E29<>"",F29<=100,G29>=2) -> TRUE
A30: 2020-03 | B30: =VALUE(LEFT(A30,4)) -> 2020 | C30: =VALUE(RIGHT(A30,2)) -> 3 | D30: KJA | E30: 0.012271 | F30: 18.391 | G30: 9 | H30: =AND(E30<>"",F30<=100,G30>=2) -> TRUE
A31: 2020-03 | B31: =VALUE(LEFT(A31,4)) -> 2020 | C31: =VALUE(RIGHT(A31,2)) -> 3 | D31: Reference | E31: 0.020031 | F31: 36.872 | G31: 9 | H31: =AND(E31<>"",F31<=100,G31>=2) -> TRUE
A32: 2020-04 | B32: =VALUE(LEFT(A32,4)) -> 2020 | C32: =VALUE(RIGHT(A32,2)) -> 4 | D32: KJA | E32: 0.027344 | F32: 18.205 | G32: 8 | H32: =AND(E32<>"",F32<=100,G32>=2) -> TRUE
A33: 2020-04 | B33: =VALUE(LEFT(A33,4)) -> 2020 | C33: =VALUE(RIGHT(A33,2)) -> 4 | D33: Reference | E33: 0.063072 | F33: 16.582 | G33: 8 | H33: =AND(E33<>"",F33<=100,G33>=2) -> TRUE
A34: 2020-05 | B34: =VALUE(LEFT(A34,4)) -> 2020 | C34: =VALUE(RIGHT(A34,2)) -> 5 | D34: KJA | G34: 0 | H34: =AND(E34<>"",F34<=100,G34>=2) -> FALSE
A35: 2020-05 | B35: =VALUE(LEFT(A35,4)) -> 2020 | C35: =VALUE(RIGHT(A35,2)) -> 5 | D35: Reference | G35: 0 | H35: =AND(E35<>"",F35<=100,G35>=2) -> FALSE
A36: 2020-06 | B36: =VALUE(LEFT(A36,4)) -> 2020 | C36: =VALUE(RIGHT(A36,2)) -> 6 | D36: KJA | E36: -0.009387 | F36: 13.278 | G36: 10 | H36: =AND(E36<>"",F36<=100,G36>=2) -> TRUE
A37: 2020-06 | B37: =VALUE(LEFT(A37,4)) -> 2020 | C37: =VALUE(RIGHT(A37,2)) -> 6 | D37: Reference | E37: 0.02347 | F37: 7.264 | G37: 10 | H37: =AND(E37<>"",F37<=100,G37>=2) -> TRUE
A38: 2020-07 | B38: =VALUE(LEFT(A38,4)) -> 2020 | C38: =VALUE(RIGHT(A38,2)) -> 7 | D38: KJA | E38: -0.005134 | F38: 12.856 | G38: 10 | H38: =AND(E38<>"",F38<=100,G38>=2) -> TRUE
A39: 2020-07 | B39: =VALUE(LEFT(A39,4)) -> 2020 | C39: =VALUE(RIGHT(A39,2)) -> 7 | D39: Reference | E39: -0.001738 | F39: 6.915 | G39: 10 | H39: =AND(E39<>"",F39<=100,G39>=2) -> TRUE
A40: 2020-08 | B40: =VALUE(LEFT(A40,4)) -> 2020 | C40: =VALUE(RIGHT(A40,2)) -> 8 | D40: KJA | E40: -0.002381 | F40: 14.457 | G40: 9 | H40: =AND(E40<>"",F40<=100,G40>=2) -> TRUE
A41: 2020-08 | B41: =VALUE(LEFT(A41,4)) -> 2020 | C41: =VALUE(RIGHT(A41,2)) -> 8 | D41: Reference | E41: 0.013551 | F41: 32.022 | G41: 9 | H41: =AND(E41<>"",F41<=100,G41>=2) -> TRUE
A42: 2020-09 | B42: =VALUE(LEFT(A42,4)) -> 2020 | C42: =VALUE(RIGHT(A42,2)) -> 9 | D42: KJA | E42: 0.008385 | F42: 23.541 | G42: 9 | H42: =AND(E42<>"",F42<=100,G42>=2) -> TRUE
A43: 2020-09 | B43: =VALUE(LEFT(A43,4)) -> 2020 | C43: =VALUE(RIGHT(A43,2)) -> 9 | D43: Reference | E43: -0.010743 | F43: 9.218 | G43: 9 | H43: =AND(E43<>"",F43<=100,G43>=2) -> TRUE
...

Sheet V1_Zona_Awal
A1: date | B1: tahun | C1: bulan | D1: zone | E1: NDCI | F1: TURB | G1: n_images | H1: QC_lolos | J1: Zona perkiraan awal. Pembanding saja.
A2: 2019-01 | B2: =VALUE(LEFT(A2,4)) -> 2019 | C2: =VALUE(RIGHT(A2,2)) -> 1 | D2: KJA | E2: 0.029868 | F2: 45.766 | G2: 7 | H2: =AND(E2<>"",F2<=100,G2>=2) -> TRUE
A3: 2019-01 | B3: =VALUE(LEFT(A3,4)) -> 2019 | C3: =VALUE(RIGHT(A3,2)) -> 1 | D3: Reference | E3: 0.050975 | F3: 29.663 | G3: 7 | H3: =AND(E3<>"",F3<=100,G3>=2) -> TRUE
A4: 2019-02 | B4: =VALUE(LEFT(A4,4)) -> 2019 | C4: =VALUE(RIGHT(A4,2)) -> 2 | D4: KJA | E4: 0.018417 | F4: 44.497 | G4: 15 | H4: =AND(E4<>"",F4<=100,G4>=2) -> TRUE
A5: 2019-02 | B5: =VALUE(LEFT(A5,4)) -> 2019 | C5: =VALUE(RIGHT(A5,2)) -> 2 | D5: Reference | E5: 0.012468 | F5: 31.447 | G5: 15 | H5: =AND(E5<>"",F5<=100,G5>=2) -> TRUE
A6: 2019-03 | B6: =VALUE(LEFT(A6,4)) -> 2019 | C6: =VALUE(RIGHT(A6,2)) -> 3 | D6: KJA | E6: 0.002771 | F6: 19.243 | G6: 18 | H6: =AND(E6<>"",F6<=100,G6>=2) -> TRUE
A7: 2019-03 | B7: =VALUE(LEFT(A7,4)) -> 2019 | C7: =VALUE(RIGHT(A7,2)) -> 3 | D7: Reference | E7: 0.001087 | F7: 19.389 | G7: 18 | H7: =AND(E7<>"",F7<=100,G7>=2) -> TRUE
A8: 2019-04 | B8: =VALUE(LEFT(A8,4)) -> 2019 | C8: =VALUE(RIGHT(A8,2)) -> 4 | D8: KJA | E8: -0.048524 | F8: 8.67 | G8: 5 | H8: =AND(E8<>"",F8<=100,G8>=2) -> TRUE
A9: 2019-04 | B9: =VALUE(LEFT(A9,4)) -> 2019 | C9: =VALUE(RIGHT(A9,2)) -> 4 | D9: Reference | E9: 0.003645 | F9: 24.559 | G9: 5 | H9: =AND(E9<>"",F9<=100,G9>=2) -> TRUE
A10: 2019-05 | B10: =VALUE(LEFT(A10,4)) -> 2019 | C10: =VALUE(RIGHT(A10,2)) -> 5 | D10: KJA | E10: 0.042784 | F10: 10.748 | G10: 8 | H10: =AND(E10<>"",F10<=100,G10>=2) -> TRUE
A11: 2019-05 | B11: =VALUE(LEFT(A11,4)) -> 2019 | C11: =VALUE(RIGHT(A11,2)) -> 5 | D11: Reference | E11: 0.016632 | F11: 12.058 | G11: 8 | H11: =AND(E11<>"",F11<=100,G11>=2) -> TRUE
A12: 2019-06 | B12: =VALUE(LEFT(A12,4)) -> 2019 | C12: =VALUE(RIGHT(A12,2)) -> 6 | D12: KJA | E12: 0.078472 | F12: 12.931 | G12: 3 | H12: =AND(E12<>"",F12<=100,G12>=2) -> TRUE
A13: 2019-06 | B13: =VALUE(LEFT(A13,4)) -> 2019 | C13: =VALUE(RIGHT(A13,2)) -> 6 | D13: Reference | E13: 0.05851 | F13: 28.158 | G13: 3 | H13: =AND(E13<>"",F13<=100,G13>=2) -> TRUE
... A17: 2019-08 | B17: =VALUE(LEFT(A17,4)) -> 2019 | C17: =VALUE(RIGHT(A17,2)) -> 8 | D17: Reference | E17: 0.018252 | F17: 30.109 | G17: 7 | H17: =AND(E17<>"",F17<=100,G17>=2) -> TRUE
A18: 2019-09 | B18: =VALUE(LEFT(A18,4)) -> 2019 | C18: =VALUE(RIGHT(A18,2)) -> 9 | D18: KJA | G18: 0 | H18: =AND(E18<>"",F18<=100,G18>=2) -> FALSE
A19: 2019-09 | B19: =VALUE(LEFT(A19,4)) -> 2019 | C19: =VALUE(RIGHT(A19,2)) -> 9 | D19: Reference | G19: 0 | H19: =AND(E19<>"",F19<=100,G19>=2) -> FALSE
A20: 2019-10 | B20: =VALUE(LEFT(A20,4)) -> 2019 | C20: =VALUE(RIGHT(A20,2)) -> 10 | D20: KJA | G20: 2 | H20: =AND(E20<>"",F20<=100,G20>=2) -> FALSE
A21: 2019-10 | B21: =VALUE(LEFT(A21,4)) -> 2019 | C21: =VALUE(RIGHT(A21,2)) -> 10 | D21: Reference | E21: 0.021791 | F21: 71.109 | G21: 2 | H21: =AND(E21<>"",F21<=100,G21>=2) -> TRUE
A22: 2019-11 | B22: =VALUE(LEFT(A22,4)) -> 2019 | C22: =VALUE(RIGHT(A22,2)) -> 11 | D22: KJA | G22: 5 | H22: =AND(E22<>"",F22<=100,G22>=2) -> FALSE
A23: 2019-11 | B23: =VALUE(LEFT(A23,4)) -> 2019 | C23: =VALUE(RIGHT(A23,2)) -> 11 | D23: Reference | E23: 0.017054 | F23: 66.624 | G23: 5 | H23: =AND(E23<>"",F23<=100,G23>=2) -> TRUE
A24: 2019-12 | B24: =VALUE(LEFT(A24,4)) -> 2019 | C24: =VALUE(RIGHT(A24,2)) -> 12 | D24: KJA | E24: -0.001229 | F24: 19.765 | G24: 6 | H24: =AND(E24<>"",F24<=100,G24>=2) -> TRUE
A25: 2019-12 | B25: =VALUE(LEFT(A25,4)) -> 2019 | C25: =VALUE(RIGHT(A25,2)) -> 12 | D25: Reference | E25: 0.006213 | F25: 31.211 | G25: 6 | H25: =AND(E25<>"",F25<=100,G25>=2) -> TRUE
A26: 2020-01 | B26: =VALUE(LEFT(A26,4)) -> 2020 | C26: =VALUE(RIGHT(A26,2)) -> 1 | D26: KJA | E26: 0.048051 | F26: 25.31 | G26: 12 | H26: =AND(E26<>"",F26<=100,G26>=2) -> TRUE
A27: 2020-01 | B27: =VALUE(LEFT(A27,4)) -> 2020 | C27: =VALUE(RIGHT(A27,2)) -> 1 | D27: Reference | E27: -0.00728 | F27: 39.956 | G27: 12 | H27: =AND(E27<>"",F27<=100,G27>=2) -> TRUE
A28: 2020-02 | B28: =VALUE(LEFT(A28,4)) -> 2020 | C28: =VALUE(RIGHT(A28,2)) -> 2 | D28: KJA | E28: 0.055894 | F28: 17.363 | G28: 12 | H28: =AND(E28<>"",F28<=100,G28>=2) -> TRUE
A29: 2020-02 | B29: =VALUE(LEFT(A29,4)) -> 2020 | C29: =VALUE(RIGHT(A29,2)) -> 2 | D29: Reference | E29: 0.034839 | F29: 25.579 | G29: 12 | H29: =AND(E29<>"",F29<=100,G29>=2) -> TRUE
A30: 2020-03 | B30: =VALUE(LEFT(A30,4)) -> 2020 | C30: =VALUE(RIGHT(A30,2)) -> 3 | D30: KJA | E30: 0.008412 | F30: 18.837 | G30: 9 | H30: =AND(E30<>"",F30<=100,G30>=2) -> TRUE
A31: 2020-03 | B31: =VALUE(LEFT(A31,4)) -> 2020 | C31: =VALUE(RIGHT(A31,2)) -> 3 | D31: Reference | E31: 0.012151 | F31: 36.274 | G31: 9 | H31: =AND(E31<>"",F31<=100,G31>=2) -> TRUE
A32: 2020-04 | B32: =VALUE(LEFT(A32,4)) -> 2020 | C32: =VALUE(RIGHT(A32,2)) -> 4 | D32: KJA | E32: 0.064711 | F32: 31.32 | G32: 8 | H32: =AND(E32<>"",F32<=100,G32>=2) -> TRUE
A33: 2020-04 | B33: =VALUE(LEFT(A33,4)) -> 2020 | C33: =VALUE(RIGHT(A33,2)) -> 4 | D33: Reference | E33: 0.05367 | F33: 16.934 | G33: 8 | H33: =AND(E33<>"",F33<=100,G33>=2) -> TRUE
A34: 2020-05 | B34: =VALUE(LEFT(A34,4)) -> 2020 | C34: =VALUE(RIGHT(A34,2)) -> 5 | D34: KJA | G34: 0 | H34: =AND(E34<>"",F34<=100,G34>=2) -> FALSE
A35: 2020-05 | B35: =VALUE(LEFT(A35,4)) -> 2020 | C35: =VALUE(RIGHT(A35,2)) -> 5 | D35: Reference | G35: 0 | H35: =AND(E35<>"",F35<=100,G35>=2) -> FALSE
A36: 2020-06 | B36: =VALUE(LEFT(A36,4)) -> 2020 | C36: =VALUE(RIGHT(A36,2)) -> 6 | D36: KJA | E36: -0.008669 | F36: 9.216 | G36: 10 | H36: =AND(E36<>"",F36<=100,G36>=2) -> TRUE
A37: 2020-06 | B37: =VALUE(LEFT(A37,4)) -> 2020 | C37: =VALUE(RIGHT(A37,2)) -> 6 | D37: Reference | E37: 0.01953 | F37: 17.474 | G37: 10 | H37: =AND(E37<>"",F37<=100,G37>=2) -> TRUE
A38: 2020-07 | B38: =VALUE(LEFT(A38,4)) -> 2020 | C38: =VALUE(RIGHT(A38,2)) -> 7 | D38: KJA | E38: 0.004299 | F38: 10.962 | G38: 10 | H38: =AND(E38<>"",F38<=100,G38>=2) -> TRUE
A39: 2020-07 | B39: =VALUE(LEFT(A39,4)) -> 2020 | C39: =VALUE(RIGHT(A39,2)) -> 7 | D39: Reference | E39: 0.016096 | F39: 16.265 | G39: 10 | H39: =AND(E39<>"",F39<=100,G39>=2) -> TRUE
A40: 2020-08 | B40: =VALUE(LEFT(A40,4)) -> 2020 | C40: =VALUE(RIGHT(A40,2)) -> 8 | D40: KJA | E40: 0.018734 | F40: 18.409 | G40: 9 | H40: =AND(E40<>"",F40<=100,G40>=2) -> TRUE
A41: 2020-08 | B41: =VALUE(LEFT(A41,4)) -> 2020 | C41: =VALUE(RIGHT(A41,2)) -> 8 | D41: Reference | E41: 0.011789 | F41: 22.594 | G41: 9 | H41: =AND(E41<>"",F41<=100,G41>=2) -> TRUE
A42: 2020-09 | B42: =VALUE(LEFT(A42,4)) -> 2020 | C42: =VALUE(RIGHT(A42,2)) -> 9 | D42: KJA | E42: 0.000881 | F42: 23.992 | G42: 9 | H42: =AND(E42<>"",F42<=100,G42>=2) -> TRUE
A43: 2020-09 | B43: =VALUE(LEFT(A43,4)) -> 2020 | C43: =VALUE(RIGHT(A43,2)) -> 9 | D43: Reference | E43: 0.041668 | F43: 31.223 | G43: 9 | H43: =AND(E43<>"",F43<=100,G43>=2) -> TRUE
...

Sheet V2_Ditolak
A1: date | B1: tahun | C1: bulan | D1: zone | E1: NDCI | F1: TURB | G1: n_images | H1: QC_lolos | J1: DITOLAK: referensi terkontaminasi (TURB tinggi).
A2: 2019-01 | B2: =VALUE(LEFT(A2,4)) -> 2019 | C2: =VALUE(RIGHT(A2,2)) -> 1 | D2: KJA | E2: 0.048788 | F2: 31.509 | G2: 7 | H2: =AND(E2<>"",F2<=100,G2>=2) -> TRUE
A3: 2019-01 | B3: =VALUE(LEFT(A3,4)) -> 2019 | C3: =VALUE(RIGHT(A3,2)) -> 1 | D3: Reference | G3: 7 | H3: =AND(E3<>"",F3<=100,G3>=2) -> FALSE
A4: 2019-02 | B4: =VALUE(LEFT(A4,4)) -> 2019 | C4: =VALUE(RIGHT(A4,2)) -> 2 | D4: KJA | E4: 0.008792 | F4: 24.241 | G4: 15 | H4: =AND(E4<>"",F4<=100,G4>=2) -> TRUE
A5: 2019-02 | B5: =VALUE(LEFT(A5,4)) -> 2019 | C5: =VALUE(RIGHT(A5,2)) -> 2 | D5: Reference | E5: 0.005667 | F5: 756.501 | G5: 15 | H5: =AND(E5<>"",F5<=100,G5>=2) -> FALSE
A6: 2019-03 | B6: =VALUE(LEFT(A6,4)) -> 2019 | C6: =VALUE(RIGHT(A6,2)) -> 3 | D6: KJA | E6: 0.022084 | F6: 25.995 | G6: 18 | H6: =AND(E6<>"",F6<=100,G6>=2) -> TRUE
A7: 2019-03 | B7: =VALUE(LEFT(A7,4)) -> 2019 | C7: =VALUE(RIGHT(A7,2)) -> 3 | D7: Reference | E7: 0.034043 | F7: 377.218 | G7: 18 | H7: =AND(E7<>"",F7<=100,G7>=2) -> FALSE
A8: 2019-04 | B8: =VALUE(LEFT(A8,4)) -> 2019 | C8: =VALUE(RIGHT(A8,2)) -> 4 | D8: KJA | E8: -0.04818 | F8: 15.263 | G8: 5 | H8: =AND(E8<>"",F8<=100,G8>=2) -> TRUE
A9: 2019-04 | B9: =VALUE(LEFT(A9,4)) -> 2019 | C9: =VALUE(RIGHT(A9,2)) -> 4 | D9: Reference | G9: 5 | H9: =AND(E9<>"",F9<=100,G9>=2) -> FALSE
A10: 2019-05 | B10: =VALUE(LEFT(A10,4)) -> 2019 | C10: =VALUE(RIGHT(A10,2)) -> 5 | D10: KJA | E10: -0.011804 | F10: 14.52 | G10: 8 | H10: =AND(E10<>"",F10<=100,G10>=2) -> TRUE
A11: 2019-05 | B11: =VALUE(LEFT(A11,4)) -> 2019 | C11: =VALUE(RIGHT(A11,2)) -> 5 | D11: Reference | E11: 0.057129 | F11: 76.233 | G11: 8 | H11: =AND(E11<>"",F11<=100,G11>=2) -> TRUE
A12: 2019-06 | B12: =VALUE(LEFT(A12,4)) -> 2019 | C12: =VALUE(RIGHT(A12,2)) -> 6 | D12: KJA | E12: 0.057428 | F12: 19.417 | G12: 3 | H12: =AND(E12<>"",F12<=100,G12>=2) -> TRUE
A13: 2019-06 | B13: =VALUE(LEFT(A13,4)) -> 2019 | C13: =VALUE(RIGHT(A13,2)) -> 6 | D13: Reference | E13: 0.104391 | F13: 65.333 | G13: 3 | H13: =AND(E13<>"",F13<=100,G13>=2) -> TRUE
A14: 2019-07 | B14: =VALUE(LEFT(A14,4)) -> 2019 | C14: =VALUE(RIGHT(A14,2)) -> 7 | D14: KJA | E14: 0.007141 | F14: 14.462 | G14: 8 | H14: =AND(E14<>"",F14<=100,G14>=2) -> TRUE
A15: 2019-07 | B15: =VALUE(LEFT(A15,4)) -> 2019 | C15: =VALUE(RIGHT(A15,2)) -> 7 | D15: Reference | E15: 0.042336 | F15: 98.4 | G15: 8 | H15: =AND(E15<>"",F15<=100,G15>=2) -> TRUE
A16: 2019-08 | B16: =VALUE(LEFT(A16,4)) -> 2019 | C16: =VALUE(RIGHT(A16,2)) -> 8 | D16: KJA | E16: 0.030884 | F16: 29.181 | G16: 7 | H16: =AND(E16<>"",F16<=100,G16>=2) -> TRUE
A17: 2019-08 | B17: =VALUE(LEFT(A17,4)) -> 2019 | C17: =VALUE(RIGHT(A17,2)) -> 8 | D17: Reference | E17: 0.005338 | F17: 487.554 | G17: 7 | H17: =AND(E17<>"",F17<=100,G17>=2) -> FALSE
A18: 2019-09 | B18: =VALUE(LEFT(A18,4)) -> 2019 | C18: =VALUE(RIGHT(A18,2)) -> 9 | D18: KJA | G18: 0 | H18: =AND(E18<>"",F18<=100,G18>=2) -> FALSE
A19: 2019-09 | B19: =VALUE(LEFT(A19,4)) -> 2019 | C19: =VALUE(RIGHT(A19,2)) -> 9 | D19: Reference | G19: 0 | H19: =AND(E19<>"",F19<=100,G19>=2) -> FALSE
A20: 2019-10 | B20: =VALUE(LEFT(A20,4)) -> 2019 | C20: =VALUE(RIGHT(A20,2)) -> 10 | D20: KJA | G20: 2 | H20: =AND(E20<>"",F20<=100,G20>=2) -> FALSE
A21: 2019-10 | B21: =VALUE(LEFT(A21,4)) -> 2019 | C21: =VALUE(RIGHT(A21,2)) -> 10 | D21: Reference | E21: 0.002651 | F21: 618.746 | G21: 2 | H21: =AND(E21<>"",F21<=100,G21>=2) -> FALSE
A22: 2019-11 | B22: =VALUE(LEFT(A22,4)) -> 2019 | C22: =VALUE(RIGHT(A22,2)) -> 11 | D22: KJA | G22: 5 | H22: =AND(E22<>"",F22<=100,G22>=2) -> FALSE
A23: 2019-11 | B23: =VALUE(LEFT(A23,4)) -> 2019 | C23: =VALUE(RIGHT(A23,2)) -> 11 | D23: Reference | E23: 0.019156 | F23: 423.556 | G23: 5 | H23: =AND(E23<>"",F23<=100,G23>=2) -> FALSE
A24: 2019-12 | B24: =VALUE(LEFT(A24,4)) -> 2019 | C24: =VALUE(RIGHT(A24,2)) -> 12 | D24: KJA | E24: 0.014985 | F24: 26.461 | G24: 6 | H24: =AND(E24<>"",F24<=100,G24>=2) -> TRUE
A25: 2019-12 | B25: =VALUE(LEFT(A25,4)) -> 2019 | C25: =VALUE(RIGHT(A25,2)) -> 12 | D25: Reference | E25: 0.01009 | F25: 465.156 | G25: 6 | H25: =AND(E25<>"",F25<=100,G25>=2) -> FALSE
A26: 2020-01 | B26: =VALUE(LEFT(A26,4)) -> 2020 | C26: =VALUE(RIGHT(A26,2)) -> 1 | D26: KJA | E26: 0.03491 | F26: 21.988 | G26: 12 | H26: =AND(E26<>"",F26<=100,G26>=2) -> TRUE
A27: 2020-01 | B27: =VALUE(LEFT(A27,4)) -> 2020 | C27: =VALUE(RIGHT(A27,2)) -> 1 | D27: Reference | E27: 0.004573 | F27: 886.405 | G27: 12 | H27: =AND(E27<>"",F27<=100,G27>=2) -> FALSE
A28: 2020-02 | B28: =VALUE(LEFT(A28,4)) -> 2020 | C28: =VALUE(RIGHT(A28,2)) -> 2 | D28: KJA | E28: 0.032421 | F28: 26.557 | G28: 12 | H28: =AND(E28<>"",F28<=100,G28>=2) -> TRUE
A29: 2020-02 | B29: =VALUE(LEFT(A29,4)) -> 2020 | C29: =VALUE(RIGHT(A29,2)) -> 2 | D29: Reference | E29: 0.00445 | F29: 675.49 | G29: 12 | H29: =AND(E29<>"",F29<=100,G29>=2) -> FALSE
A30: 2020-03 | B30: =VALUE(LEFT(A30,4)) -> 2020 | C30: =VALUE(RIGHT(A30,2)) -> 3 | D30: KJA | E30: 0.013056 | F30: 19.093 | G30: 9 | H30: =AND(E30<>"",F30<=100,G30>=2) -> TRUE
A31: 2020-03 | B31: =VALUE(LEFT(A31,4)) -> 2020 | C31: =VALUE(RIGHT(A31,2)) -> 3 | D31: Reference | E31: 0.01041 | F31: 566.829 | G31: 9 | H31: =AND(E31<>"",F31<=100,G31>=2) -> FALSE
A32: 2020-04 | B32: =VALUE(LEFT(A32,4)) -> 2020 | C32: =VALUE(RIGHT(A32,2)) -> 4 | D32: KJA | E32: 0.026341 | F32: 18.355 | G32: 8 | H32: =AND(E32<>"",F32<=100,G32>=2) -> TRUE
A33: 2020-04 | B33: =VALUE(LEFT(A33,4)) -> 2020 | C33: =VALUE(RIGHT(A33,2)) -> 4 | D33: Reference | E33: 0.122007 | F33: 81.167 | G33: 8 | H33: =AND(E33<>"",F33<=100,G33>=2) -> TRUE
A34: 2020-05 | B34: =VALUE(LEFT(A34,4)) -> 2020 | C34: =VALUE(RIGHT(A34,2)) -> 5 | D34: KJA | G34: 0 | H34: =AND(E34<>"",F34<=100,G34>=2) -> FALSE
A35: 2020-05 | B35: =VALUE(LEFT(A35,4)) -> 2020 | C35: =VALUE(RIGHT(A35,2)) -> 5 | D35: Reference | G35: 0 | H35: =AND(E35<>"",F35<=100,G35>=2) -> FALSE
A36: 2020-06 | B36: =VALUE(LEFT(A36,4)) -> 2020 | C36: =VALUE(RIGHT(A36,2)) -> 6 | D36: KJA | E36: -0.013381 | F36: 13.143 | G36: 10 | H36: =AND(E36<>"",F36<=100,G36>=2) -> TRUE
A37: 2020-06 | B37: =VALUE(LEFT(A37,4)) -> 2020 | C37: =VALUE(RIGHT(A37,2)) -> 6 | D37: Reference | E37: 0.007741 | F37: 777.169 | G37: 10 | H37: =AND(E37<>"",F37<=100,G37>=2) -> FALSE
A38: 2020-07 | B38: =VALUE(LEFT(A38,4)) -> 2020 | C38: =VALUE(RIGHT(A38,2)) -> 7 | D38: KJA | E38: -0.005597 | F38: 12.86 | G38: 10 | H38: =AND(E38<>"",F38<=100,G38>=2) -> TRUE
A39: 2020-07 | B39: =VALUE(LEFT(A39,4)) -> 2020 | C39: =VALUE(RIGHT(A39,2)) -> 7 | D39: Reference | E39: 0.063458 | F39: 502.973 | G39: 10 | H39: =AND(E39<>"",F39<=100,G39>=2) -> FALSE
A40: 2020-08 | B40: =VALUE(LEFT(A40,4)) -> 2020 | C40: =VALUE(RIGHT(A40,2)) -> 8 | D40: KJA | E40: -0.002001 | F40: 14.615 | G40: 9 | H40: =AND(E40<>"",F40<=100,G40>=2) -> TRUE
...

Sheet Titik_Lapangan
A1: versi | B1: titik | C1: tipe | D1: lat | E1: lon | F1: NDCI | G1: TURB | H1: catatan
A2: baru (buffer 30 m) | B2: Muara Pantai Mulia Raja | C2: impacted | D2: 2.341625 | E2: 99.062615 | F2: 0.026503 | G2: 35.184
A3: baru (buffer 30 m) | B3: Pelabuhan Balige | C3: impacted | D3: 2.340133 | E3: 99.062092 | F3: 0.049642 | G3: 75.923 | H3: tertinggi; cek pengaruh dermaga dan kapal
A4: baru (buffer 30 m) | B4: Tepi Danau Bistro | C4: shore | D4: 2.335157 | E4: 99.056492 | F4: 0.031171 | G4: 33.584
A5: baru (buffer 30 m) | B5: Tepi Danau Damar | C5: shore | D5: 2.341117 | E5: 99.052531 | F5: 0.037734 | G5: 23.467
A6: lama (titik, tanpa buffer) | B6: Pantai Bul Bul | D6: 2.357 | E6: 99.03 | H6: kosong: titik jatuh di darat
A7: lama (titik, tanpa buffer) | B7: Pelabuhan Onan Balige | D7: 2.345 | E7: 99.058 | F7: 0.014149 | G7: 29.6
A8: lama (titik, tanpa buffer) | B8: Lumban Silintong | D8: 2.352 | E8: 99.02 | F8: 0.024414 | G8: 21.65
A9: lama (titik, tanpa buffer) | B9: Desa Meat | D9: 2.392 | E9: 98.98 | F9: 0.018602 | G9: 27.95
A10: lama (titik, tanpa buffer) | B10: Sitoluama dekat IT Del | D10: 2.381 | E10: 99.14 | H10: kosong: titik jatuh di darat
A12: Komposit Juli 2025 (VISIT_START 2025-07-01 sampai 2025-07-31). Satu nilai per titik, belum ada ulangan.

Sheet Ringkasan
A1: Ringkasan per versi (rumus, hanya baris QC_lolos = TRUE)
A2: Versi | B2: Zona | C2: Bulan lolos QC | D2: Median NDCI | E2: Rata-rata NDCI | F2: Median TURB
A3: V3_Utama | B3: KJA | C3: =COUNTIFS(V3_Utama!$D$2:$D$189,B3,V3_Utama!$H$2:$H$189,TRUE()) -> 72 | D3: {=MEDIAN(IF((V3_Utama!$D$2:$D$189=B3)*(V3_Utama!$H$2:$H$189=TRUE()),V3_Utama!$E$2:$E$189))} -> 0.0245915 | E3: =AVERAGEIFS(V3_Utama!$E$2:$E$189,V3_Utama!$D$2:$D$189,B3,V3_Utama!$H$2:$H$189,TRUE()) -> 0.021300431 | F3: {=MEDIAN(IF((V3_Utama!$D$2:$D$189=B3)*(V3_Utama!$H$2:$H$189=TRUE()),V3_Utama!$F$2:$F$189))} -> 23.067
A4: V3_Utama | B4: Reference | C4: =COUNTIFS(V3_Utama!$D$2:$D$189,B4,V3_Utama!$H$2:$H$189,TRUE()) -> 78 | D4: {=MEDIAN(IF((V3_Utama!$D$2:$D$189=B4)*(V3_Utama!$H$2:$H$189=TRUE()),V3_Utama!$E$2:$E$189))} -> 0.020204 | E4: =AVERAGEIFS(V3_Utama!$E$2:$E$189,V3_Utama!$D$2:$D$189,B4,V3_Utama!$H$2:$H$189,TRUE()) -> 0.019515821 | F4: {=MEDIAN(IF((V3_Utama!$D$2:$D$189=B4)*(V3_Utama!$H$2:$H$189=TRUE()),V3_Utama!$F$2:$F$189))} -> 21.05
A5: V1_Zona_Awal | B5: KJA | C5: =COUNTIFS(V1_Zona_Awal!$D$2:$D$189,B5,V1_Zona_Awal!$H$2:$H$189,TRUE()) -> 70 | D5: {=MEDIAN(IF((V1_Zona_Awal!$D$2:$D$189=B5)*(V1_Zona_Awal!$H$2:$H$189=TRUE()),V1_Zona_Awal!$E$2:$E$189))} -> 0.029515 | E5: =AVERAGEIFS(V1_Zona_Awal!$E$2:$E$189,V1_Zona_Awal!$D$2:$D$189,B5,V1_Zona_Awal!$H$2:$H$189,TRUE()) -> 0.027039857 | F5: {=MEDIAN(IF((V1_Zona_Awal!$D$2:$D$189=B5)*(V1_Zona_Awal!$H$2:$H$189=TRUE()),V1_Zona_Awal!$F$2:$F$189))} -> 20.381
A6: V1_Zona_Awal | B6: Reference | C6: =COUNTIFS(V1_Zona_Awal!$D$2:$D$189,B6,V1_Zona_Awal!$H$2:$H$189,TRUE()) -> 77 | D6: {=MEDIAN(IF((V1_Zona_Awal!$D$2:$D$189=B6)*(V1_Zona_Awal!$H$2:$H$189=TRUE()),V1_Zona_Awal!$E$2:$E$189))} -> 0.019721 | E6: =AVERAGEIFS(V1_Zona_Awal!$E$2:$E$189,V1_Zona_Awal!$D$2:$D$189,B6,V1_Zona_Awal!$H$2:$H$189,TRUE()) -> 0.022736468 | F6: {=MEDIAN(IF((V1_Zona_Awal!$D$2:$D$189=B6)*(V1_Zona_Awal!$H$2:$H$189=TRUE()),V1_Zona_Awal!$F$2:$F$189))} -> 30.98
A7: V2_Ditolak | B7: KJA | C7: =COUNTIFS(V2_Ditolak!$D$2:$D$189,B7,V2_Ditolak!$H$2:$H$189,TRUE()) -> 73 | D7: {=MEDIAN(IF((V2_Ditolak!$D$2:$D$189=B7)*(V2_Ditolak!$H$2:$H$189=TRUE()),V2_Ditolak!$E$2:$E$189))} -> 0.024697 | E7: =AVERAGEIFS(V2_Ditolak!$E$2:$E$189,V2_Ditolak!$D$2:$D$189,B7,V2_Ditolak!$H$2:$H$189,TRUE()) -> 0.020698603 | F7: {=MEDIAN(IF((V2_Ditolak!$D$2:$D$189=B7)*(V2_Ditolak!$H$2:$H$189=TRUE()),V2_Ditolak!$F$2:$F$189))} -> 23.68
A8: V2_Ditolak | B8: Reference | C8: =COUNTIFS(V2_Ditolak!$D$2:$D$189,B8,V2_Ditolak!$H$2:$H$189,TRUE()) -> 26 | D8: {=MEDIAN(IF((V2_Ditolak!$D$2:$D$189=B8)*(V2_Ditolak!$H$2:$H$189=TRUE()),V2_Ditolak!$E$2:$E$189))} -> 0.134945 | E8: =AVERAGEIFS(V2_Ditolak!$E$2:$E$189,V2_Ditolak!$D$2:$D$189,B8,V2_Ditolak!$H$2:$H$189,TRUE()) -> 0.12990112 | F8: {=MEDIAN(IF((V2_Ditolak!$D$2:$D$189=B8)*(V2_Ditolak!$H$2:$H$189=TRUE()),V2_Ditolak!$F$2:$F$189))} -> 69.742
A10: Hasil uji statistik (dihitung dengan Python scipy pada baris QC_lolos; skrip analyze.py, analyze2.py)
A11: Uji | B11: Data | C11: Hasil | D11: Arti
A12: Wilcoxon berpasangan KJA vs Ref | B12: V3, 71 bulan berpasangan | C12: median selisih +0,0005; KJA > Ref di 36/71 bulan (51%); p = 0,66 | D12: Tidak ada beda bermakna antarzona
A13: Wilcoxon berpasangan KJA vs Ref | B13: V1, 67 bulan | C13: median selisih +0,0059; KJA > Ref di 40/67 (60%); p = 0,27 | D13: Tidak bermakna; zona KJA V1 bukan lokasi keramba terverifikasi
A14: Wilcoxon berpasangan KJA vs Ref | B14: V2, 23 bulan | C14: KJA < Ref; p < 0,001 | D14: DITOLAK: referensi terkontaminasi
A15: Kruskal-Wallis antarmusim | B15: V3 KJA | C15: p = 0,077 | D15: Belum bermakna (batas 0,05)
A16: Kruskal-Wallis antarmusim | B16: V3 Ref | C16: p = 0,31 | D16: Tidak bermakna
A17: Tren Mann-Kendall + Sen slope | B17: V3 KJA | C17: tau +0,13; p = 0,11; +0,0015 per tahun (CI -0,0004 sampai +0,0036) | D17: Arah naik, belum bermakna
A18: Tren Mann-Kendall + Sen slope | B18: V3 Ref | C18: tau +0,09; p = 0,27; +0,0014 per tahun | D18: Arah naik, belum bermakna
A19: Spearman NDCI vs TURB | B19: V3 KJA | C19: r = 0,46; p < 0,001 | D19: NDCI zona KJA ikut naik saat keruh; waspada efek tepi atau sedimen
A20: Spearman NDCI vs TURB | B20: V3 Ref | C20: r = 0,13; p = 0,28 | D20: Tidak berhubungan
A21: Juni 2025 KJA | B21: V3 | C21: NDCI 0,0621; persentil 98,6 dari seluruh bulan KJA; 14 citra | D21: Lonjakan 1 sampai 2 bulan sebelum laporan ikan mati 2 Agu 2025; referensi juga naik (0,038)

Sheet Musiman
A1: Bulan | B1: Median NDCI KJA | C1: Median NDCI Referensi | D1: n bulan KJA
A2: Jan | B2: {=MEDIAN(IF((V3_Utama!$C$2:$C$189=1)*(V3_Utama!$D$2:$D$189="KJA")*(V3_Utama!$H$2:$H$189=TRUE()),V3_Utama!$E$2:$E$189))} -> 0.024336 | C2: {=MEDIAN(IF((V3_Utama!$C$2:$C$189=1)*(V3_Utama!$D$2:$D$189="Reference")*(V3_Utama!$H$2:$H$189=TRUE()),V3_Utama!$E$2:$E$189))} -> 0.0189005 | D2: =COUNTIFS(V3_Utama!$C$2:$C$189,1,V3_Utama!$D$2:$D$189,"KJA",V3_Utama!$H$2:$H$189,TRUE()) -> 7
A3: Feb | B3: {=MEDIAN(IF((V3_Utama!$C$2:$C$189=2)*(V3_Utama!$D$2:$D$189="KJA")*(V3_Utama!$H$2:$H$189=TRUE()),V3_Utama!$E$2:$E$189))} -> 0.015302 | C3: {=MEDIAN(IF((V3_Utama!$C$2:$C$189=2)*(V3_Utama!$D$2:$D$189="Reference")*(V3_Utama!$H$2:$H$189=TRUE()),V3_Utama!$E$2:$E$189))} -> 0.002044 | D3: =COUNTIFS(V3_Utama!$C$2:$C$189,2,V3_Utama!$D$2:$D$189,"KJA",V3_Utama!$H$2:$H$189,TRUE()) -> 6
A4: Mar | B4: {=MEDIAN(IF((V3_Utama!$C$2:$C$189=3)*(V3_Utama!$D$2:$D$189="KJA")*(V3_Utama!$H$2:$H$189=TRUE()),V3_Utama!$E$2:$E$189))} -> 0.022491 | C4: {=MEDIAN(IF((V3_Utama!$C$2:$C$189=3)*(V3_Utama!$D$2:$D$189="Reference")*(V3_Utama!$H$2:$H$189=TRUE()),V3_Utama!$E$2:$E$189))} -> 0.007966 | D4: =COUNTIFS(V3_Utama!$C$2:$C$189,3,V3_Utama!$D$2:$D$189,"KJA",V3_Utama!$H$2:$H$189,TRUE()) -> 7
A5: Apr | B5: {=MEDIAN(IF((V3_Utama!$C$2:$C$189=4)*(V3_Utama!$D$2:$D$189="KJA")*(V3_Utama!$H$2:$H$189=TRUE()),V3_Utama!$E$2:$E$189))} -> 0.018965 | C5: {=MEDIAN(IF((V3_Utama!$C$2:$C$189=4)*(V3_Utama!$D$2:$D$189="Reference")*(V3_Utama!$H$2:$H$189=TRUE()),V3_Utama!$E$2:$E$189))} -> 0.01365 | D5: =COUNTIFS(V3_Utama!$C$2:$C$189,4,V3_Utama!$D$2:$D$189,"KJA",V3_Utama!$H$2:$H$189,TRUE()) -> 7
A6: Mei | B6: {=MEDIAN(IF((V3_Utama!$C$2:$C$189=5)*(V3_Utama!$D$2:$D$189="KJA")*(V3_Utama!$H$2:$H$189=TRUE()),V3_Utama!$E$2:$E$189))} -> 0.0127405 | C6: {=MEDIAN(IF((V3_Utama!$C$2:$C$189=5)*(V3_Utama!$D$2:$D$189="Reference")*(V3_Utama!$H$2:$H$189=TRUE()),V3_Utama!$E$2:$E$189))} -> 0.024485 | D6: =COUNTIFS(V3_Utama!$C$2:$C$189,5,V3_Utama!$D$2:$D$189,"KJA",V3_Utama!$H$2:$H$189,TRUE()) -> 6
A7: Jun | B7: {=MEDIAN(IF((V3_Utama!$C$2:$C$189=6)*(V3_Utama!$D$2:$D$189="KJA")*(V3_Utama!$H$2:$H$189=TRUE()),V3_Utama!$E$2:$E$189))} -> 0.049441 | C7: {=MEDIAN(IF((V3_Utama!$C$2:$C$189=6)*(V3_Utama!$D$2:$D$189="Reference")*(V3_Utama!$H$2:$H$189=TRUE()),V3_Utama!$E$2:$E$189))} -> 0.02347 | D7: =COUNTIFS(V3_Utama!$C$2:$C$189,6,V3_Utama!$D$2:$D$189,"KJA",V3_Utama!$H$2:$H$189,TRUE()) -> 6
A8: Jul | B8: {=MEDIAN(IF((V3_Utama!$C$2:$C$189=7)*(V3_Utama!$D$2:$D$189="KJA")*(V3_Utama!$H$2:$H$189=TRUE()),V3_Utama!$E$2:$E$189))} -> 0.0244295 | C8: {=MEDIAN(IF((V3_Utama!$C$2:$C$189=7)*(V3_Utama!$D$2:$D$189="Reference")*(V3_Utama!$H$2:$H$189=TRUE()),V3_Utama!$E$2:$E$189))} -> 0.0158425 | D8: =COUNTIFS(V3_Utama!$C$2:$C$189,7,V3_Utama!$D$2:$D$189,"KJA",V3_Utama!$H$2:$H$189,TRUE()) -> 8
A9: Agu | B9: {=MEDIAN(IF((V3_Utama!$C$2:$C$189=8)*(V3_Utama!$D$2:$D$189="KJA")*(V3_Utama!$H$2:$H$189=TRUE()),V3_Utama!$E$2:$E$189))} -> 0.027234 | C9: {=MEDIAN(IF((V3_Utama!$C$2:$C$189=8)*(V3_Utama!$D$2:$D$189="Reference")*(V3_Utama!$H$2:$H$189=TRUE()),V3_Utama!$E$2:$E$189))} -> 0.021132 | D9: =COUNTIFS(V3_Utama!$C$2:$C$189,8,V3_Utama!$D$2:$D$189,"KJA",V3_Utama!$H$2:$H$189,TRUE()) -> 8
A10: Sep | B10: {=MEDIAN(IF((V3_Utama!$C$2:$C$189=9)*(V3_Utama!$D$2:$D$189="KJA")*(V3_Utama!$H$2:$H$189=TRUE()),V3_Utama!$E$2:$E$189))} -> 0.024421 | C10: {=MEDIAN(IF((V3_Utama!$C$2:$C$189=9)*(V3_Utama!$D$2:$D$189="Reference")*(V3_Utama!$H$2:$H$189=TRUE()),V3_Utama!$E$2:$E$189))} -> 0.024451 | D10: =COUNTIFS(V3_Utama!$C$2:$C$189,9,V3_Utama!$D$2:$D$189,"KJA",V3_Utama!$H$2:$H$189,TRUE()) -> 6
A11: Okt | B11: {=MEDIAN(IF((V3_Utama!$C$2:$C$189=10)*(V3_Utama!$D$2:$D$189="KJA")*(V3_Utama!$H$2:$H$189=TRUE()),V3_Utama!$E$2:$E$189))} -> 0.0330545 | C11: {=MEDIAN(IF((V3_Utama!$C$2:$C$189=10)*(V3_Utama!$D$2:$D$189="Reference")*(V3_Utama!$H$2:$H$189=TRUE()),V3_Utama!$E$2:$E$189))} -> -0.003577 | D11: =COUNTIFS(V3_Utama!$C$2:$C$189,10,V3_Utama!$D$2:$D$189,"KJA",V3_Utama!$H$2:$H$189,TRUE()) -> 4
A12: Nov | B12: {=MEDIAN(IF((V3_Utama!$C$2:$C$189=11)*(V3_Utama!$D$2:$D$189="KJA")*(V3_Utama!$H$2:$H$189=TRUE()),V3_Utama!$E$2:$E$189))} -> 0.025109 | C12: {=MEDIAN(IF((V3_Utama!$C$2:$C$189=11)*(V3_Utama!$D$2:$D$189="Reference")*(V3_Utama!$H$2:$H$189=TRUE()),V3_Utama!$E$2:$E$189))} -> 0.0332 | D12: =COUNTIFS(V3_Utama!$C$2:$C$189,11,V3_Utama!$D$2:$D$189,"KJA",V3_Utama!$H$2:$H$189,TRUE()) -> 3
A13: Des | B13: {=MEDIAN(IF((V3_Utama!$C$2:$C$189=12)*(V3_Utama!$D$2:$D$189="KJA")*(V3_Utama!$H$2:$H$189=TRUE()),V3_Utama!$E$2:$E$189))} -> 0.0379525 | C13: {=MEDIAN(IF((V3_Utama!$C$2:$C$189=12)*(V3_Utama!$D$2:$D$189="Reference")*(V3_Utama!$H$2:$H$189=TRUE()),V3_Utama!$E$2:$E$189))} -> 0.022083 | D13: =COUNTIFS(V3_Utama!$C$2:$C$189,12,V3_Utama!$D$2:$D$189,"KJA",V3_Utama!$H$2:$H$189,TRUE()) -> 4
